Workbook

Sheet EFB
A1: CalendarDT | B1: StartTime | C1: Time | D1: ProgramTitle | E1: SeriesEpisodeTitle | F1: - | G1: CC | H1: A/I/E | I1: Status | J1: QA Notes | K1: Air Date | L1: Time | M1: Column1 | N1: TVG Title | O1: Duration | P1: Link Information | Q1: Link Duration | R1: EP.NO | S1: Episode Title | T1: Subtitle | U1: TV Rating | V1: Captioning | W1: Audio Level | X1: HDTV Level | Y1: DVS | Z1: SAP | AA1: Aspect Ratio | AB1: Subtitled | AC1: Program Information | AD1: Feed | AE1: SPG | AF1: Event Date | AG1: Airing Type | AH1: Showing Type | AI1: Paid For By | AJ1: Program Type | AK1: Program Part | AL1: Part No./Total | AM1: Film Rating | AN1: Year | AO1: Credits | AP1: Color Type | AQ1: Category | AR1: 3D | AS1: PID | AT1: Schedule ID | AU1: Language | AV1: DST | AW1: Creation User | AX1: Creation Date | AY1: Last Update User | AZ1: Last Update Date | BB1: Time | BC1: Title | BD1: EpTitle | BE1: Raw Time | BF1: Cosmo Time | BG1: Add Time | BH1: Time
C2: =BH2 -> 0.041666667 | U2: None | V2: None | W2: None | X2: None | Y2: FALSE | Z2: FALSE | AA2: 4:3 Fullscreen | AB2: FALSE | AC2: ESF | AD2: 0 | AE2: FALSE | AJ2: Series Episode | AP2: Color | AQ2: Sports | AS2: 19874297 | AT2: 279643702 | AU2: French | AV2: TRUE | AW2: mjayaram | AX2: 42216.124 | AY2: mjayaram | AZ2: 42220.114 | BB2: =IF(BE2=BF2,"Yes","No") -> No | BC2: =IF(EFB!$N2=Table1[[#This Row],[ProgramTitle]],"Yes","No") -> Yes | BD2: =IF(EFB!$S2=Table1[[#This Row],[SeriesEpisodeTitle]],"Yes","No") -> Yes | BE2: =TIME(HOUR(C2),MINUTE(C2),SECOND(0)) -> 0.041666667 | BF2: =TIME(HOUR(L2),MINUTE(L2),SECOND(0)) -> 0 | BG2: 0.041666667 | BH2: =Table1[[#This Row],[StartTime]]+$BG$2 -> 0.041666667
C3: =BH3 -> 0.041666667 | V3: None | W3: None | X3: None | Y3: FALSE | Z3: FALSE | AA3: 4:3 Fullscreen | AB3: FALSE | AC3: ESF-EF2 | AD3: 0 | AE3: FALSE | AJ3: Series Episode | AP3: Color | AQ3: Sports | AS3: 17388856 | AT3: 259431250 | AU3: French | AV3: TRUE | AW3: XListImporter (1426490) | AX3: 42205.274 | AY3: mjayaram | AZ3: 42220.114 | BB3: =IF(BE3=BF3,"Yes","No") -> No | BC3: =IF(EFB!$N3=Table1[[#This Row],[ProgramTitle]],"Yes","No") -> Yes | BD3: =IF(EFB!$S3=Table1[[#This Row],[SeriesEpisodeTitle]],"Yes","No") -> Yes | BE3: =TIME(HOUR(C3),MINUTE(C3),SECOND(0)) -> 0.041666667 | BF3: =TIME(HOUR(L3),MINUTE(L3),SECOND(0)) -> 0 | BH3: =Table1[[#This Row],[StartTime]]+$BG$2 -> 0.041666667
C4: =BH4 -> 0.041666667 | U4: None | V4: None | W4: None | X4: None | Y4: FALSE | Z4: FALSE | AA4: 4:3 Fullscreen | AB4: FALSE | AD4: 0 | AE4: FALSE | AJ4: Series Episode | AP4: Color | AQ4: Sports | AS4: 27537279 | AT4: 259431290 | AU4: French | AV4: TRUE | AW4: XListImporter (1426490) | AX4: 42205.274 | AY4: mjayaram | AZ4: 42220.114 | BB4: =IF(BE4=BF4,"Yes","No") -> No | BC4: =IF(EFB!$N4=Table1[[#This Row],[ProgramTitle]],"Yes","No") -> Yes | BD4: =IF(EFB!$S4=Table1[[#This Row],[SeriesEpisodeTitle]],"Yes","No") -> Yes | BE4: =TIME(HOUR(C4),MINUTE(C4),SECOND(0)) -> 0.041666667 | BF4: =TIME(HOUR(L4),MINUTE(L4),SECOND(0)) -> 0 | BH4: =Table1[[#This Row],[StartTime]]+$BG$2 -> 0.041666667
C5: =BH5 -> 0.041666667 | U5: None | V5: None | W5: None | X5: None | Y5: FALSE | Z5: FALSE | AA5: 4:3 Fullscreen | AB5: FALSE | AD5: 0 | AE5: FALSE | AJ5: Series Master | AP5: Color | AQ5: Sports | AS5: 27580021 | AT5: 259702249 | AU5: French | AV5: TRUE | AW5: XListImporter (1426490) | AX5: 42205.274 | AY5: mjayaram | AZ5: 42220.114 | BB5: =IF(BE5=BF5,"Yes","No") -> No | BC5: =IF(EFB!$N5=Table1[[#This Row],[ProgramTitle]],"Yes","No") -> Yes | BD5: =IF(EFB!$S5=Table1[[#This Row],[SeriesEpisodeTitle]],"Yes","No") -> Yes | BE5: =TIME(HOUR(C5),MINUTE(C5),SECOND(0)) -> 0.041666667 | BF5: =TIME(HOUR(L5),MINUTE(L5),SECOND(0)) -> 0 | BH5: =Table1[[#This Row],[StartTime]]+$BG$2 -> 0.041666667
C6: =BH6 -> 0.041666667 | U6: None | V6: None | W6: None | X6: None | Y6: FALSE | Z6: FALSE | AA6: 4:3 Fullscreen | AB6: FALSE | AD6: 0 | AE6: FALSE | AJ6: Series Master | AP6: Color | AQ6: Sports | AS6: 27580033 | AT6: 259431313 | AU6: French | AV6: TRUE | AW6: XListImporter (1426490) | AX6: 42205.274 | AY6: mjayaram | AZ6: 42220.114 | BB6: =IF(BE6=BF6,"Yes","No") -> No | BC6: =IF(EFB!$N6=Table1[[#This Row],[ProgramTitle]],"Yes","No") -> Yes | BD6: =IF(EFB!$S6=Table1[[#This Row],[SeriesEpisodeTitle]],"Yes","No") -> Yes | BE6: =TIME(HOUR(C6),MINUTE(C6),SECOND(0)) -> 0.041666667 | BF6: =TIME(HOUR(L6),MINUTE(L6),SECOND(0)) -> 0 | BH6: =Table1[[#This Row],[StartTime]]+$BG$2 -> 0.041666667
C7: =BH7 -> 0.041666667 | U7: None | V7: None | W7: None | X7: None | Y7: FALSE | Z7: FALSE | AA7: 4:3 Fullscreen | AB7: FALSE | AD7: 0 | AE7: FALSE | AJ7: Series Master | AP7: Color | AQ7: Sports | AS7: 20847475 | AT7: 259431262 | AU7: French | AV7: TRUE | AW7: XListImporter (1426490) | AX7: 42205.274 | AY7: mjayaram | AZ7: 42220.114 | BB7: =IF(BE7=BF7,"Yes","No") -> No | BC7: =IF(EFB!$N7=Table1[[#This Row],[ProgramTitle]],"Yes","No") -> Yes | BD7: =IF(EFB!$S7=Table1[[#This Row],[SeriesEpisodeTitle]],"Yes","No") -> Yes | BE7: =TIME(HOUR(C7),MINUTE(C7),SECOND(0)) -> 0.041666667 | BF7: =TIME(HOUR(L7),MINUTE(L7),SECOND(0)) -> 0 | BH7: =Table1[[#This Row],[StartTime]]+$BG$2 -> 0.041666667
C8: =BH8 -> 0.041666667 | U8: None | V8: None | W8: None | X8: None | Y8: FALSE | Z8: FALSE | AA8: 4:3 Fullscreen | AB8: FALSE | AC8: ESF - EF2 | AD8: 0 | AE8: FALSE | AJ8: Series Master | AP8: Color | AQ8: Sports | AS8: 15151796 | AT8: 285575784 | AU8: French | AV8: TRUE | AW8: mjayaram | AX8: 42220.114 | AY8: mjayaram | AZ8: 42220.114 | BB8: =IF(BE8=BF8,"Yes","No") -> No | BC8: =IF(EFB!$N8=Table1[[#This Row],[ProgramTitle]],"Yes","No") -> Yes | BD8: =IF(EFB!$S8=Table1[[#This Row],[SeriesEpisodeTitle]],"Yes","No") -> Yes | BE8: =TIME(HOUR(C8),MINUTE(C8),SECOND(0)) -> 0.041666667 | BF8: =TIME(HOUR(L8),MINUTE(L8),SECOND(0)) -> 0 | BH8: =Table1[[#This Row],[StartTime]]+$BG$2 -> 0.041666667
C9: =BH9 -> 0.041666667 | U9: None | V9: None | W9: None | X9: None | Y9: FALSE | Z9: FALSE | AA9: 4:3 Fullscreen | AB9: FALSE | AC9: ISIS | AD9: 0 | AE9: FALSE | AJ9: Series Master | AP9: Color | AQ9: Sports | AS9: 15398057 | AT9: 259431237 | AU9: French | AV9: TRUE | AW9: XListImporter (1426490) | AX9: 42205.274 | AY9: mjayaram | AZ9: 42220.114 | BB9: =IF(BE9=BF9,"Yes","No") -> No | BC9: =IF(EFB!$N9=Table1[[#This Row],[ProgramTitle]],"Yes","No") -> Yes | BD9: =IF(EFB!$S9=Table1[[#This Row],[SeriesEpisodeTitle]],"Yes","No") -> Yes | BE9: =TIME(HOUR(C9),MINUTE(C9),SECOND(0)) -> 0.041666667 | BF9: =TIME(HOUR(L9),MINUTE(L9),SECOND(0)) -> 0 | BH9: =Table1[[#This Row],[StartTime]]+$BG$2 -> 0.041666667
C10: =BH10 -> 0.041666667 | U10: None | V10: None | W10: None | X10: None | Y10: FALSE | Z10: FALSE | AA10: 4:3 Fullscreen | AB10: FALSE | AC10: ESF | AD10: 0 | AE10: FALSE | AJ10: Series Episode | AP10: Color | AQ10: Sports | AS10: 24324661 | AT10: 259431280 | AU10: French | AV10: TRUE | AW10: XListImporter (1426490) | AX10: 42205.274 | AY10: mjayaram | AZ10: 42220.114 | BB10: =IF(BE10=BF10,"Yes","No") -> No | BC10: =IF(EFB!$N10=Table1[[#This Row],[ProgramTitle]],"Yes","No") -> Yes | BD10: =IF(EFB!$S10=Table1[[#This Row],[SeriesEpisodeTitle]],"Yes","No") -> Yes | BE10: =TIME(HOUR(C10),MINUTE(C10),SECOND(0)) -> 0.041666667 | BF10: =TIME(HOUR(L10),MINUTE(L10),SECOND(0)) -> 0 | BH10: =Table1[[#This Row],[StartTime]]+$BG$2 -> 0.041666667
C11: =BH11 -> 0.041666667 | U11: None | V11: None | W11: None | X11: None | Y11: FALSE | Z11: FALSE | AA11: 4:3 Fullscreen | AB11: FALSE | AC11: ESF | AD11: 0 | AE11: FALSE | AJ11: Series Episode | AP11: Color | AQ11: Sports | AS11: 24324654 | AT11: 259431278 | AU11: French | AV11: TRUE | AW11: XListImporter (1426490) | AX11: 42205.274 | AY11: mjayaram | AZ11: 42220.114 | BB11: =IF(BE11=BF11,"Yes","No") -> No | BC11: =IF(EFB!$N11=Table1[[#This Row],[ProgramTitle]],"Yes","No") -> Yes | BD11: =IF(EFB!$S11=Table1[[#This Row],[SeriesEpisodeTitle]],"Yes","No") -> Yes | BE11: =TIME(HOUR(C11),MINUTE(C11),SECOND(0)) -> 0.041666667 | BF11: =TIME(HOUR(L11),MINUTE(L11),SECOND(0)) -> 0 | BH11: =Table1[[#This Row],[StartTime]]+$BG$2 -> 0.041666667
C12: =BH12 -> 0.041666667 | U12: None | V12: None | W12: None | X12: None | Y12: FALSE | Z12: FALSE | AA12: 4:3 Fullscreen | AB12: FALSE | AC12: ESF - EF2 | AD12: 0 | AE12: FALSE | AJ12: Series Master | AP12: Color | AQ12: Sports | AS12: 15151796 | AT12: 259431223 | AU12: French | AV12: TRUE | AW12: XListImporter (1426490) | AX12: 42205.274 | AY12: mjayaram | AZ12: 42220.114 | BB12: =IF(BE12=BF12,"Yes","No") -> No | BC12: =IF(EFB!$N12=Table1[[#This Row],[ProgramTitle]],"Yes","No") -> Yes | BD12: =IF(EFB!$S12=Table1[[#This Row],[SeriesEpisodeTitle]],"Yes","No") -> Yes | BE12: =TIME(HOUR(C12),MINUTE(C12),SECOND(0)) -> 0.041666667 | BF12: =TIME(HOUR(L12),MINUTE(L12),SECOND(0)) -> 0 | BH12: =Table1[[#This Row],[StartTime]]+$BG$2 -> 0.041666667
C13: =BH13 -> 0.041666667 | U13: None | V13: None | W13: None | X13: None | Y13: FALSE | Z13: FALSE | AA13: 4:3 Fullscreen | AB13: FALSE | AD13: 0 | AE13: FALSE | AJ13: Series Master | AP13: Color | AQ13: Sports | AS13: 20847475 | AT13: 259431261 | AU13: French | AV13: TRUE | AW13: XListImporter (1426490) | AX13: 42205.274 | AY13: mjayaram | AZ13: 42220.114 | BB13: =IF(BE13=BF13,"Yes","No") -> No | BC13: =IF(EFB!$N13=Table1[[#This Row],[ProgramTitle]],"Yes","No") -> Yes | BD13: =IF(EFB!$S13=Table1[[#This Row],[SeriesEpisodeTitle]],"Yes","No") -> Yes | BE13: =TIME(HOUR(C13),MINUTE(C13),SECOND(0)) -> 0.041666667 | BF13: =TIME(HOUR(L13),MINUTE(L13),SECOND(0)) -> 0 | BH13: =Table1[[#This Row],[StartTime]]+$BG$2 -> 0.041666667
C14: =BH14 -> 0.041666667 | V14: None | W14: None | X14: None | Y14: FALSE | Z14: FALSE | AA14: 4:3 Fullscreen | AB14: FALSE | AC14: ESF-EF2 | AD14: 0 | AE14: FALSE | AJ14: Series Episode | AP14: Color | AQ14: Sports | AS14: 17388856 | AT14: 259431248 | AU14: French | AV14: TRUE | AW14: XListImporter (1426490) | AX14: 42205.274 | AY14: mjayaram | AZ14: 42220.114 | BB14: =IF(BE14=BF14,"Yes","No") -> No | BC14: =IF(EFB!$N14=Table1[[#This Row],[ProgramTitle]],"Yes","No") -> Yes | BD14: =IF(EFB!$S14=Table1[[#This Row],[SeriesEpisodeTitle]],"Yes","No") -> Yes | BE14: =TIME(HOUR(C14),MINUTE(C14),SECOND(0)) -> 0.041666667 | BF14: =TIME(HOUR(L14),MINUTE(L14),SECOND(0)) -> 0 | BH14: =Table1[[#This Row],[StartTime]]+$BG$2 -> 0.041666667
C15: =BH15 -> 0.041666667 | U15: None | V15: None | W15: None | X15: None | Y15: FALSE | Z15: FALSE | AA15: 4:3 Fullscreen | AB15: FALSE | AC15: ESF-EF2 | AD15: 0 | AE15: FALSE | AG15: Live | AJ15: Series Episode | AP15: Color | AQ15: Sports | AS15: 17359081 | AT15: 259431245 | AU15: French | AV15: TRUE | AW15: XListImporter (1426490) | AX15: 42205.274 | AY15: mjayaram | AZ15: 42220.114 | BB15: =IF(BE15=BF15,"Yes","No") -> No | BC15: =IF(EFB!$N15=Table1[[#This Row],[ProgramTitle]],"Yes","No") -> Yes | BD15: =IF(EFB!$S15=Table1[[#This Row],[SeriesEpisodeTitle]],"Yes","No") -> Yes | BE15: =TIME(HOUR(C15),MINUTE(C15),SECOND(0)) -> 0.041666667 | BF15: =TIME(HOUR(L15),MINUTE(L15),SECOND(0)) -> 0 | BH15: =Table1[[#This Row],[StartTime]]+$BG$2 -> 0.041666667
C16: =BH16 -> 0.041666667 | U16: None | V16: None | W16: None | X16: None | Y16: FALSE | Z16: FALSE | AA16: 4:3 Fullscreen | AB16: FALSE | AC16: ISIS | AD16: 0 | AE16: FALSE | AJ16: Series Episode | AP16: Color | AQ16: Sports | AS16: 27537283 | AT16: 259431291 | AU16: French | AV16: TRUE | AW16: XListImporter (1426490) | AX16: 42205.274 | AY16: mjayaram | AZ16: 42220.114 | BB16: =IF(BE16=BF16,"Yes","No") -> No | BC16: =IF(EFB!$N16=Table1[[#This Row],[ProgramTitle]],"Yes","No") -> Yes | BD16: =IF(EFB!$S16=Table1[[#This Row],[SeriesEpisodeTitle]],"Yes","No") -> Yes | BE16: =TIME(HOUR(C16),MINUTE(C16),SECOND(0)) -> 0.041666667 | BF16: =TIME(HOUR(L16),MINUTE(L16),SECOND(0)) -> 0 | BH16: =Table1[[#This Row],[StartTime]]+$BG$2 -> 0.041666667
C17: =BH17 -> 0.041666667 | U17: None | V17: None | W17: None | X17: None | Y17: FALSE | Z17: FALSE | AA17: 4:3 Fullscreen | AB17: FALSE | AD17: 0 | AE17: FALSE | AJ17: Series Master | AP17: Color | AQ17: Sports | AS17: 27569128 | AT17: 259431306 | AU17: French | AV17: TRUE | AW17: XListImporter (1426490) | AX17: 42205.274 | AY17: mjayaram | AZ17: 42220.114 | BB17: =IF(BE17=BF17,"Yes","No") -> No | BC17: =IF(EFB!$N17=Table1[[#This Row],[ProgramTitle]],"Yes","No") -> Yes | BD17: =IF(EFB!$S17=Table1[[#This Row],[SeriesEpisodeTitle]],"Yes","No") -> Yes | BE17: =TIME(HOUR(C17),MINUTE(C17),SECOND(0)) -> 0.041666667 | BF17: =TIME(HOUR(L17),MINUTE(L17),SECOND(0)) -> 0 | BH17: =Table1[[#This Row],[StartTime]]+$BG$2 -> 0.041666667
C18: =BH18 -> 0.041666667 | U18: None | V18: None | W18: None | X18: None | Y18: FALSE | Z18: FALSE | AA18: 4:3 Fullscreen | AB18: FALSE | AC18: ISIS | AD18: 0 | AE18: FALSE | AJ18: Series Episode | AP18: Color | AQ18: Sports | AS18: 27537316 | AT18: 259431298 | AU18: French | AV18: TRUE | AW18: XListImporter (1426490) | AX18: 42205.274 | AY18: mjayaram | AZ18: 42220.114 | BB18: =IF(BE18=BF18,"Yes","No") -> No | BC18: =IF(EFB!$N18=Table1[[#This Row],[ProgramTitle]],"Yes","No") -> Yes | BD18: =IF(EFB!$S18=Table1[[#This Row],[SeriesEpisodeTitle]],"Yes","No") -> Yes | BE18: =TIME(HOUR(C18),MINUTE(C18),SECOND(0)) -> 0.041666667 | BF18: =TIME(HOUR(L18),MINUTE(L18),SECOND(0)) -> 0 | BH18: =Table1[[#This Row],[StartTime]]+$BG$2 -> 0.041666667
C19: =BH19 -> 0.041666667 | U19: None | V19: None | W19: None | X19: None | Y19: FALSE | Z19: FALSE | AA19: 4:3 Fullscreen | AB19: FALSE | AC19: ISIS | AD19: 0 | AE19: FALSE | AJ19: Series Episode | AP19: Color | AQ19: Sports | AS19: 27537317 | AT19: 259431299 | AU19: French | AV19: TRUE | AW19: XListImporter (1426490) | AX19: 42205.274 | AY19: mjayaram | AZ19: 42220.114 | BB19: =IF(BE19=BF19,"Yes","No") -> No | BC19: =IF(EFB!$N19=Table1[[#This Row],[ProgramTitle]],"Yes","No") -> Yes | BD19: =IF(EFB!$S19=Table1[[#This Row],[SeriesEpisodeTitle]],"Yes","No") -> Yes | BE19: =TIME(HOUR(C19),MINUTE(C19),SECOND(0)) -> 0.041666667 | BF19: =TIME(HOUR(L19),MINUTE(L19),SECOND(0)) -> 0 | BH19: =Table1[[#This Row],[StartTime]]+$BG$2 -> 0.041666667
C20: =BH20 -> 0.041666667 | U20: None | V20: None | W20: None | X20: None | Y20: FALSE | Z20: FALSE | AA20: 4:3 Fullscreen | AB20: FALSE | AC20: ESF | AD20: 0 | AE20: FALSE | AJ20: Series Master | AP20: Color | AQ20: Sports | AS20: 15340174 | AT20: 259431234 | AU20: French | AV20: TRUE | AW20: XListImporter (1426490) | AX20: 42205.274 | AY20: mjayaram | AZ20: 42220.114 | BB20: =IF(BE20=BF20,"Yes","No") -> No | BC20: =IF(EFB!$N20=Table1[[#This Row],[ProgramTitle]],"Yes","No") -> Yes | BD20: =IF(EFB!$S20=Table1[[#This Row],[SeriesEpisodeTitle]],"Yes","No") -> Yes | BE20: =TIME(HOUR(C20),MINUTE(C20),SECOND(0)) -> 0.041666667 | BF20: =TIME(HOUR(L20),MINUTE(L20),SECOND(0)) -> 0 | BH20: =Table1[[#This Row],[StartTime]]+$BG$2 -> 0.041666667
C21: =BH21 -> 0.041666667 | U21: None | V21: None | W21: None | X21: None | Y21: FALSE | Z21: FALSE | AA21: 4:3 Fullscreen | AB21: FALSE | AC21: ESF-EF2 | AD21: 0 | AE21: FALSE | AJ21: Series Episode | AP21: Color | AQ21: Sports | AS21: 17359081 | AT21: 259431244 | AU21: French | AV21: TRUE | AW21: XListImporter (1426490) | AX21: 42205.274 | AY21: mjayaram | AZ21: 42220.114 | BB21: =IF(BE21=BF21,"Yes","No") -> No | BC21: =IF(EFB!$N21=Table1[[#This Row],[ProgramTitle]],"Yes","No") -> Yes | BD21: =IF(EFB!$S21=Table1[[#This Row],[SeriesEpisodeTitle]],"Yes","No") -> Yes | BE21: =TIME(HOUR(C21),MINUTE(C21),SECOND(0)) -> 0.041666667 | BF21: =TIME(HOUR(L21),MINUTE(L21),SECOND(0)) -> 0 | BH21: =Table1[[#This Row],[StartTime]]+$BG$2 -> 0.041666667
C22: =BH22 -> 0.041666667 | U22: None | V22: None | W22: None | X22: None | Y22: FALSE | Z22: FALSE | AA22: 4:3 Fullscreen | AB22: FALSE | AD22: 0 | AE22: FALSE | AJ22: Series Master | AP22: Color | AQ22: Sports | AS22: 20847475 | AT22: 259431264 | AU22: French | AV22: TRUE | AW22: XListImporter (1426490) | AX22: 42205.274 | AY22: mjayaram | AZ22: 42220.114 | BB22: =IF(BE22=BF22,"Yes","No") -> No | BC22: =IF(EFB!$N22=Table1[[#This Row],[ProgramTitle]],"Yes","No") -> Yes | BD22: =IF(EFB!$S22=Table1[[#This Row],[SeriesEpisodeTitle]],"Yes","No") -> Yes | BE22: =TIME(HOUR(C22),MINUTE(C22),SECOND(0)) -> 0.041666667 | BF22: =TIME(HOUR(L22),MINUTE(L22),SECOND(0)) -> 0 | BH22: =Table1[[#This Row],[StartTime]]+$BG$2 -> 0.041666667
C23: =BH23 -> 0.041666667 | U23: None | V23: None | W23: None | X23: None | Y23: FALSE | Z23: FALSE | AA23: 4:3 Fullscreen | AB23: FALSE | AC23: Closedown French Channels | AD23: 0 | AE23: FALSE | AJ23: Series Master | AP23: Color | AQ23: Other | AS23: 22808296 | AT23: 259431272 | AU23: French | AV23: TRUE | AW23: asprimont | AX23: 42205.286 | AY23: asprimont | AZ23: 42205.286 | BB23: =IF(BE23=BF23,"Yes","No") -> No | BC23: =IF(EFB!$N23=Table1[[#This Row],[ProgramTitle]],"Yes","No") -> Yes | BD23: =IF(EFB!$S23=Table1[[#This Row],[SeriesEpisodeTitle]],"Yes","No") -> Yes | BE23: =TIME(HOUR(C23),MINUTE(C23),SECOND(0)) -> 0.041666667 | BF23: =TIME(HOUR(L23),MINUTE(L23),SECOND(0)) -> 0 | BH23: =Table1[[#This Row],[StartTime]]+$BG$2 -> 0.041666667
C24: =BH24 -> 0.041666667 | U24: None | V24: None | W24: None | X24: None | Y24: FALSE | Z24: FALSE | AA24: 4:3 Fullscreen | AB24: FALSE | AC24: ESF | AD24: 0 | AE24: FALSE | AJ24: Series Master | AP24: Color | AQ24: Sports | AS24: 15340174 | AT24: 259478648 | AU24: French | AV24: TRUE | AW24: XListImporter (1426490) | AX24: 42205.274 | AY24: XListImporter (1426490) | AZ24: 42205.274 | BB24: =IF(BE24=BF24,"Yes","No") -> No | BC24: =IF(EFB!$N24=Table1[[#This Row],[ProgramTitle]],"Yes","No") -> Yes | BD24: =IF(EFB!$S24=Table1[[#This Row],[SeriesEpisodeTitle]],"Yes","No") -> Yes | BE24: =TIME(HOUR(C24),MINUTE(C24),SECOND(0)) -> 0.041666667 | BF24: =TIME(HOUR(L24),MINUTE(L24),SECOND(0)) -> 0 | BH24: =Table1[[#This Row],[StartTime]]+$BG$2 -> 0.041666667
C25: =BH25 -> 0.041666667 | U25: None | V25: None | W25: None | X25: None | Y25: FALSE | Z25: FALSE | AA25: 4:3 Fullscreen | AB25: FALSE | AC25: ESF-EF2 EFB-EFA | AD25: 0 | AE25: FALSE | AJ25: Series Episode | AP25: Color | AQ25: Sports | AS25: 27580034 | AT25: 259478865 | AU25: French | AV25: TRUE | AW25: XListImporter (1426490) | AX25: 42205.274 | AY25: XListImporter (1426490) | AZ25: 42205.274 | BB25: =IF(BE25=BF25,"Yes","No") -> No | BC25: =IF(EFB!$N25=Table1[[#This Row],[ProgramTitle]],"Yes","No") -> Yes | BD25: =IF(EFB!$S25=Table1[[#This Row],[SeriesEpisodeTitle]],"Yes","No") -> Yes | BE25: =TIME(HOUR(C25),MINUTE(C25),SECOND(0)) -> 0.041666667 | BF25: =TIME(HOUR(L25),MINUTE(L25),SECOND(0)) -> 0 | BH25: =Table1[[#This Row],[StartTime]]+$BG$2 -> 0.041666667
C26: =BH26 -> 0.041666667 | U26: None | V26: None | W26: None | X26: None | Y26: FALSE | Z26: FALSE | AA26: 4:3 Fullscreen | AB26: FALSE | AD26: 0 | AE26: FALSE | AJ26: Series Master | AP26: Color | AQ26: Sports | AS26: 27569128 | AT26: 259478827 | AU26: French | AV26: TRUE | AW26: XListImporter (1426490) | AX26: 42205.274 | AY26: XListImporter (1426490) | AZ26: 42205.274 | BB26: =IF(BE26=BF26,"Yes","No") -> No | BC26: =IF(EFB!$N26=Table1[[#This Row],[ProgramTitle]],"Yes","No") -> Yes | BD26: =IF(EFB!$S26=Table1[[#This Row],[SeriesEpisodeTitle]],"Yes","No") -> Yes | BE26: =TIME(HOUR(C26),MINUTE(C26),SECOND(0)) -> 0.041666667 | BF26: =TIME(HOUR(L26),MINUTE(L26),SECOND(0)) -> 0 | BH26: =Table1[[#This Row],[StartTime]]+$BG$2 -> 0.041666667
C27: =BH27 -> 0.041666667 | U27: None | V27: None | W27: None | X27: None | Y27: FALSE | Z27: FALSE | AA27: 4:3 Fullscreen | AB27: FALSE | AC27: ISIS | AD27: 0 | AE27: FALSE | AJ27: Series Episode | AP27: Color | AQ27: Sports | AS27: 27537316 | AT27: 259478823 | AU27: French | AV27: TRUE | AW27: XListImporter (1426490) | AX27: 42205.274 | AY27: XListImporter (1426490) | AZ27: 42205.274 | BB27: =IF(BE27=BF27,"Yes","No") -> No | BC27: =IF(EFB!$N27=Table1[[#This Row],[ProgramTitle]],"Yes","No") -> Yes | BD27: =IF(EFB!$S27=Table1[[#This Row],[SeriesEpisodeTitle]],"Yes","No") -> Yes | BE27: =TIME(HOUR(C27),MINUTE(C27),SECOND(0)) -> 0.041666667 | BF27: =TIME(HOUR(L27),MINUTE(L27),SECOND(0)) -> 0 | BH27: =Table1[[#This Row],[StartTime]]+$BG$2 -> 0.041666667
C28: =BH28 -> 0.041666667 | U28: None | V28: None | W28: None | X28: None | Y28: FALSE | Z28: FALSE | AA28: 4:3 Fullscreen | AB28: FALSE | AC28: ISIS | AD28: 0 | AE28: FALSE | AJ28: Series Episode | AP28: Color | AQ28: Sports | AS28: 27537317 | AT28: 259478824 | AU28: French | AV28: TRUE | AW28: XListImporter (1426490) | AX28: 42205.274 | AY28: XListImporter (1426490) | AZ28: 42205.274 | BB28: =IF(BE28=BF28,"Yes","No") -> No | BC28: =IF(EFB!$N28=Table1[[#This Row],[ProgramTitle]],"Yes","No") -> Yes | BD28: =IF(EFB!$S28=Table1[[#This Row],[SeriesEpisodeTitle]],"Yes","No") -> Yes | BE28: =TIME(HOUR(C28),MINUTE(C28),SECOND(0)) -> 0.041666667 | BF28: =TIME(HOUR(L28),MINUTE(L28),SECOND(0)) -> 0 | BH28: =Table1[[#This Row],[StartTime]]+$BG$2 -> 0.041666667
C29: =BH29 -> 0.041666667 | U29: None | V29: None | W29: None | X29: None | Y29: FALSE | Z29: FALSE | AA29: 4:3 Fullscreen | AB29: FALSE | AC29: ESF | AD29: 0 | AE29: FALSE | AJ29: Series Episode | AP29: Color | AQ29: Sports | AS29: 22642711 | AT29: 259478778 | AU29: French | AV29: TRUE | AW29: XListImporter (1426490) | AX29: 42205.274 | AY29: XListImporter (1426490) | AZ29: 42205.274 | BB29: =IF(BE29=BF29,"Yes","No") -> No | BC29: =IF(EFB!$N29=Table1[[#This Row],[ProgramTitle]],"Yes","No") -> Yes | BD29: =IF(EFB!$S29=Table1[[#This Row],[SeriesEpisodeTitle]],"Yes","No") -> Yes | BE29: =TIME(HOUR(C29),MINUTE(C29),SECOND(0)) -> 0.041666667 | BF29: =TIME(HOUR(L29),MINUTE(L29),SECOND(0)) -> 0 | BH29: =Table1[[#This Row],[StartTime]]+$BG$2 -> 0.041666667
C30: =BH30 -> 0.041666667 | U30: None | V30: None | W30: None | X30: None | Y30: FALSE | Z30: FALSE | AA30: 4:3 Fullscreen | AB30: FALSE | AC30: ESF-EF2 | AD30: 0 | AE30: FALSE | AJ30: Series Episode | AP30: Color | AQ30: Sports | AS30: 17359081 | AT30: 259478690 | AU30: French | AV30: TRUE | AW30: XListImporter (1426490) | AX30: 42205.274 | AY30: XListImporter (1426490) | AZ30: 42205.274 | BB30: =IF(BE30=BF30,"Yes","No") -> No | BC30: =IF(EFB!$N30=Table1[[#This Row],[ProgramTitle]],"Yes","No") -> Yes | BD30: =IF(EFB!$S30=Table1[[#This Row],[SeriesEpisodeTitle]],"Yes","No") -> Yes | BE30: =TIME(HOUR(C30),MINUTE(C30),SECOND(0)) -> 0.041666667 | BF30: =TIME(HOUR(L30),MINUTE(L30),SECOND(0)) -> 0 | BH30: =Table1[[#This Row],[StartTime]]+$BG$2 -> 0.041666667
C31: =BH31 -> 0.041666667 | U31: None | V31: None | W31: None | X31: None | Y31: FALSE | Z31: FALSE | AA31: 4:3 Fullscreen | AB31: FALSE | AC31: ESF-EF2 EFB-EFA | AD31: 0 | AE31: FALSE | AJ31: Series Episode | AP31: Color | AQ31: Sports | AS31: 27580034 | AT31: 259478862 | AU31: French | AV31: TRUE | AW31: XListImporter (1426490) | AX31: 42205.274 | AY31: XListImporter (1426490) | AZ31: 42205.274 | BB31: =IF(BE31=BF31,"Yes","No") -> No | BC31: =IF(EFB!$N31=Table1[[#This Row],[ProgramTitle]],"Yes","No") -> Yes | BD31: =IF(EFB!$S31=Table1[[#This Row],[SeriesEpisodeTitle]],"Yes","No") -> Yes | BE31: =TIME(HOUR(C31),MINUTE(C31),SECOND(0)) -> 0.041666667 | BF31: =TIME(HOUR(L31),MINUTE(L31),SECOND(0)) -> 0 | BH31: =Table1[[#This Row],[StartTime]]+$BG$2 -> 0.041666667
C32: =BH32 -> 0.041666667 | U32: None | V32: None | W32: None | X32: None | Y32: FALSE | Z32: FALSE | AA32: 4:3 Fullscreen | AB32: FALSE | AC32: ESF-EF2 | AD32: 0 | AE32: FALSE | AJ32: Series Episode | AP32: Color | AQ32: Sports | AS32: 17359081 | AT32: 259478689 | AU32: French | AV32: TRUE | AW32: XListImporter (1426490) | AX32: 42205.274 | AY32: XListImporter (1426490) | AZ32: 42205.274 | BB32: =IF(BE32=BF32,"Yes","No") -> No | BC32: =IF(EFB!$N32=Table1[[#This Row],[ProgramTitle]],"Yes","No") -> Yes | BD32: =IF(EFB!$S32=Table1[[#This Row],[SeriesEpisodeTitle]],"Yes","No") -> Yes | BE32: =TIME(HOUR(C32),MINUTE(C32),SECOND(0)) -> 0.041666667 | BF32: =TIME(HOUR(L32),MINUTE(L32),SECOND(0)) -> 0 | BH32: =Table1[[#This Row],[StartTime]]+$BG$2 -> 0.041666667
C33: =BH33 -> 0.041666667 | U33: None | V33: None | W33: None | X33: None | Y33: FALSE | Z33: FALSE | AA33: 4:3 Fullscreen | AB33: FALSE | AC33: 3ème étape | AD33: 0 | AE33: FALSE | AG33: Live | AJ33: Series Episode | AP33: Color | AQ33: Sports | AS33: 27580025 | AT33: 259702273 | AU33: French | AV33: TRUE | AW33: XListImporter (1426490) | AX33: 42205.274 | AY33: XListImporter (1426490) | AZ33: 42205.274 | BB33: =IF(BE33=BF33,"Yes","No") -> No | BC33: =IF(EFB!$N33=Table1[[#This Row],[ProgramTitle]],"Yes","No") -> Yes | BD33: =IF(EFB!$S33=Table1[[#This Row],[SeriesEpisodeTitle]],"Yes","No") -> Yes | BE33: =TIME(HOUR(C33),MINUTE(C33),SECOND(0)) -> 0.041666667 | BF33: =TIME(HOUR(L33),MINUTE(L33),SECOND(0)) -> 0 | BH33: =Table1[[#This Row],[StartTime]]+$BG$2 -> 0.041666667
C34: =BH34 -> 0.041666667 | U34: None | V34: None | W34: None | X34: None | Y34: FALSE | Z34: FALSE | AA34: 4:3 Fullscreen | AB34: FALSE | AC34: ESF-EF2 | AD34: 0 | AE34: FALSE | AJ34: Series Episode | AP34: Color | AQ34: Sports | AS34: 17359081 | AT34: 259478691 | AU34: French | AV34: TRUE | AW34: XListImporter (1426490) | AX34: 42205.274 | AY34: mjayaram | AZ34: 42219.117 | BB34: =IF(BE34=BF34,"Yes","No") -> No | BC34: =IF(EFB!$N34=Table1[[#This Row],[ProgramTitle]],"Yes","No") -> Yes | BD34: =IF(EFB!$S34=Table1[[#This Row],[SeriesEpisodeTitle]],"Yes","No") -> Yes | BE34: =TIME(HOUR(C34),MINUTE(C34),SECOND(0)) -> 0.041666667 | BF34: =TIME(HOUR(L34),MINUTE(L34),SECOND(0)) -> 0 | BH34: =Table1[[#This Row],[StartTime]]+$BG$2 -> 0.041666667
C35: =BH35 -> 0.041666667 | U35: None | X35: None | Y35: FALSE | Z35: FALSE | AA35: 4:3 Fullscreen | AB35: FALSE | AC35: ESF-EF2 | AD35: 0 | AE35: FALSE | AJ35: Series Episode | AP35: Color | AQ35: Sports | AS35: 17359083 | AT35: 259478702 | AU35: French | AV35: TRUE | AW35: XListImporter (1426490) | AX35: 42205.274 | AY35: mjayaram | AZ35: 42219.117 | BB35: =IF(BE35=BF35,"Yes","No") -> No | BC35: =IF(EFB!$N35=Table1[[#This Row],[ProgramTitle]],"Yes","No") -> Yes | BD35: =IF(EFB!$S35=Table1[[#This Row],[SeriesEpisodeTitle]],"Yes","No") -> Yes | BE35: =TIME(HOUR(C35),MINUTE(C35),SECOND(0)) -> 0.041666667 | BF35: =TIME(HOUR(L35),MINUTE(L35),SECOND(0)) -> 0 | BH35: =Table1[[#This Row],[StartTime]]+$BG$2 -> 0.041666667
C36: =BH36 -> 0.041666667 | U36: None | V36: None | W36: None | X36: None | Y36: FALSE | Z36: FALSE | AA36: 4:3 Fullscreen | AB36: FALSE | AC36: ESF | AD36: 0 | AE36: FALSE | AJ36: Series Episode | AP36: Color | AQ36: Sports | AS36: 22642711 | AT36: 259478777 | AU36: French | AV36: TRUE | AW36: XListImporter (1426490) | AX36: 42205.274 | AY36: mjayaram | AZ36: 42219.117 | BB36: =IF(BE36=BF36,"Yes","No") -> No | BC36: =IF(EFB!$N36=Table1[[#This Row],[ProgramTitle]],"Yes","No") -> Yes | BD36: =IF(EFB!$S36=Table1[[#This Row],[SeriesEpisodeTitle]],"Yes","No") -> Yes | BE36: =TIME(HOUR(C36),MINUTE(C36),SECOND(0)) -> 0.041666667 | BF36: =TIME(HOUR(L36),MINUTE(L36),SECOND(0)) -> 0 | BH36: =Table1[[#This Row],[StartTime]]+$BG$2 -> 0.041666667
C37: =BH37 -> 0.041666667 | U37: None | V37: None | W37: None | X37: None | Y37: FALSE | Z37: FALSE | AA37: 4:3 Fullscreen | AB37: FALSE | AC37: ESF-EF2 EFB-EFA | AD37: 0 | AE37: FALSE | AJ37: Series Episode | AP37: Color | AQ37: Sports | AS37: 27580034 | AT37: 259478863 | AU37: French | AV37: TRUE | AW37: XListImporter (1426490) | AX37: 42205.274 | AY37: mjayaram | AZ37: 42219.117 | BB37: =IF(BE37=BF37,"Yes","No") -> No | BC37: =IF(EFB!$N37=Table1[[#This Row],[ProgramTitle]],"Yes","No") -> Yes | BD37: =IF(EFB!$S37=Table1[[#This Row],[SeriesEpisodeTitle]],"Yes","No") -> Yes | BE37: =TIME(HOUR(C37),MINUTE(C37),SECOND(0)) -> 0.041666667 | BF37: =TIME(HOUR(L37),MINUTE(L37),SECOND(0)) -> 0 | BH37: =Table1[[#This Row],[StartTime]]+$BG$2 -> 0.041666667
C38: =BH38 -> 0.041666667 | U38: None | V38: None | W38: None | X38: None | Y38: FALSE | Z38: FALSE | AA38: 4:3 Fullscreen | AB38: FALSE | AC38: ESF | AD38: 0 | AE38: FALSE | AJ38: Series Episode | AP38: Color | AQ38: Sports | AS38: 24324661 | AT38: 259478793 | AU38: French | AV38: TRUE | AW38: XListImporter (1426490) | AX38: 42205.274 | AY38: XListImporter (1426490) | AZ38: 42205.274 | BB38: =IF(BE38=BF38,"Yes","No") -> No | BC38: =IF(EFB!$N38=Table1[[#This Row],[ProgramTitle]],"Yes","No") -> Yes | BD38: =IF(EFB!$S38=Table1[[#This Row],[SeriesEpisodeTitle]],"Yes","No") -> Yes | BE38: =TIME(HOUR(C38),MINUTE(C38),SECOND(0)) -> 0.041666667 | BF38: =TIME(HOUR(L38),MINUTE(L38),SECOND(0)) -> 0 | BH38: =Table1[[#This Row],[StartTime]]+$BG$2 -> 0.041666667
C39: =BH39 -> 0.041666667 | U39: None | V39: None | W39: None | X39: None | Y39: FALSE | Z39: FALSE | AA39: 4:3 Fullscreen | AB39: FALSE | AD39: 0 | AE39: FALSE | AJ39: Series Master | AP39: Color | AQ39: Sports | AS39: 24324658 | AT39: 259478792 | AU39: French | AV39: TRUE | AW39: XListImporter (1426490) | AX39: 42205.274 | AY39: XListImporter (1426490) | AZ39: 42205.274 | BB39: =IF(BE39=BF39,"Yes","No") -> No | BC39: =IF(EFB!$N39=Table1[[#This Row],[ProgramTitle]],"Yes","No") -> Yes | BD39: =IF(EFB!$S39=Table1[[#This Row],[SeriesEpisodeTitle]],"Yes","No") -> Yes | BE39: =TIME(HOUR(C39),MINUTE(C39),SECOND(0)) -> 0.041666667 | BF39: =TIME(HOUR(L39),MINUTE(L39),SECOND(0)) -> 0 | BH39: =Table1[[#This Row],[StartTime]]+$BG$2 -> 0.041666667
C40: =BH40 -> 0.041666667 | U40: None | V40: None | W40: None | X40: None | Y40: FALSE | Z40: FALSE | AA40: 4:3 Fullscreen | AB40: FALSE | AC40: ESF | AD40: 0 | AE40: FALSE | AJ40: Series Episode | AP40: Color | AQ40: Sports | AS40: 24324654 | AT40: 259478790 | AU40: French | AV40: TRUE | AW40: XListImporter (1426490) | AX40: 42205.274 | AY40: XListImporter (1426490) | AZ40: 42205.274 | BB40: =IF(BE40=BF40,"Yes","No") -> No | BC40: =IF(EFB!$N40=Table1[[#This Row],[ProgramTitle]],"Yes","No") -> Yes | BD40: =IF(EFB!$S40=Table1[[#This Row],[SeriesEpisodeTitle]],"Yes","No") -> Yes | BE40: =TIME(HOUR(C40),MINUTE(C40),SECOND(0)) -> 0.041666667 | BF40: =TIME(HOUR(L40),MINUTE(L40),SECOND(0)) -> 0 | BH40: =Table1[[#This Row],[StartTime]]+$BG$2 -> 0.041666667
...
